Workbook

Sheet BOM Report
A1: Manufacturer | B1: MPN | C1: Quantity | D1: Alternate Manufacturer 1 | E1: Alternate MPN 1 | F1: Alternate Manufacturer 2 | G1: Alternate MPN 2 | H1: Alternate Manufacturer 3 | I1: Alternate MPN 3
A2: TDK | B2: CGA2B3X7R1E104K050BB | C2: 64 | F2: =VLOOKUP(B2,Sheet1!$F$2:$N$100,6,False) -> Samsung | G2: =VLOOKUP(B2,Sheet1!$F$2:$N$100,7,False) -> CL05B104KA54PNC | H2: =VLOOKUP(B2,Sheet1!$F$2:$N$100,8,False) | I2: =VLOOKUP(B2,Sheet1!$F$2:$N$100,9,False)
A3: TDK | B3: CGA3E3X7R1E334K080AB | C3: 19 | F3: =VLOOKUP(B3,Sheet1!$F$2:$N$100,6,False) -> Samsung | G3: =VLOOKUP(B3,Sheet1!$F$2:$N$100,7,False) -> CL10B334KA8VPNC | H3: =VLOOKUP(B3,Sheet1!$F$2:$N$100,8,False) | I3: =VLOOKUP(B3,Sheet1!$F$2:$N$100,9,False)
A4: KEMET | B4: C0805C104K1RACAUTO | C4: 2 | F4: =VLOOKUP(B4,Sheet1!$F$2:$N$100,6,False) -> Murata Electronics | G4: =VLOOKUP(B4,Sheet1!$F$2:$N$100,7,False) -> GCJ21BR72A104KA01L | H4: =VLOOKUP(B4,Sheet1!$F$2:$N$100,8,False) -> Samsung | I4: =VLOOKUP(B4,Sheet1!$F$2:$N$100,9,False) -> CL21B104KCFWPNE
A5: KEMET | B5: C0805C224K1RECAUTO | C5: 6 | F5: =VLOOKUP(B5,Sheet1!$F$2:$N$100,6,False) | G5: =VLOOKUP(B5,Sheet1!$F$2:$N$100,7,False) | H5: =VLOOKUP(B5,Sheet1!$F$2:$N$100,8,False) | I5: =VLOOKUP(B5,Sheet1!$F$2:$N$100,9,False)
A6: TDK | B6: CGA4J3X7R1E105K125AB | C6: 28 | F6: =VLOOKUP(B6,Sheet1!$F$2:$N$100,6,False) -> Samsung | G6: =VLOOKUP(B6,Sheet1!$F$2:$N$100,7,False) -> CL21B105KAFVPNE | H6: =VLOOKUP(B6,Sheet1!$F$2:$N$100,8,False) | I6: =VLOOKUP(B6,Sheet1!$F$2:$N$100,9,False)
A7: KEMET | B7: C0603C224K4RECAUTO | C7: 18 | F7: =VLOOKUP(B7,Sheet1!$F$2:$N$100,6,False) -> KEMET | G7: =VLOOKUP(B7,Sheet1!$F$2:$N$100,7,False) -> C0603C224K3RECAUTO | H7: =VLOOKUP(B7,Sheet1!$F$2:$N$100,8,False) -> KEMET | I7: =VLOOKUP(B7,Sheet1!$F$2:$N$100,9,False) -> C0603C224K3RECAUTO
A8: Murata | B8: GCM21A5C2E102JX01D | C8: 7 | F8: =VLOOKUP(B8,Sheet1!$F$2:$N$100,6,False) -> TDK | G8: =VLOOKUP(B8,Sheet1!$F$2:$N$100,7,False) -> CGA4F3C0G2E102J085AA | H8: =VLOOKUP(B8,Sheet1!$F$2:$N$100,8,False) | I8: =VLOOKUP(B8,Sheet1!$F$2:$N$100,9,False)
A9: TDK | B9: CGA3E1X7R1E105K080AC | C9: 4 | F9: =VLOOKUP(B9,Sheet1!$F$2:$N$100,6,False) -> Samsung | G9: =VLOOKUP(B9,Sheet1!$F$2:$N$100,7,False) -> CL10B105KA8VPNC | H9: =VLOOKUP(B9,Sheet1!$F$2:$N$100,8,False) | I9: =VLOOKUP(B9,Sheet1!$F$2:$N$100,9,False)
A10: Murata | B10: GCM1555C1H221JA16D | C10: 4 | F10: =VLOOKUP(B10,Sheet1!$F$2:$N$100,6,False) -> Samsung | G10: =VLOOKUP(B10,Sheet1!$F$2:$N$100,7,False) -> CL05C221JB51PNC | H10: =VLOOKUP(B10,Sheet1!$F$2:$N$100,8,False) | I10: =VLOOKUP(B10,Sheet1!$F$2:$N$100,9,False)
A11: KEMET | B11: C0603C472K4RECAUTO | C11: 5 | F11: =VLOOKUP(B11,Sheet1!$F$2:$N$100,6,False) | G11: =VLOOKUP(B11,Sheet1!$F$2:$N$100,7,False) | H11: =VLOOKUP(B11,Sheet1!$F$2:$N$100,8,False) | I11: =VLOOKUP(B11,Sheet1!$F$2:$N$100,9,False)
A12: KEMET | B12: C0603C103K4RECAUTO | C12: 6 | F12: =VLOOKUP(B12,Sheet1!$F$2:$N$100,6,False) | G12: =VLOOKUP(B12,Sheet1!$F$2:$N$100,7,False) | H12: =VLOOKUP(B12,Sheet1!$F$2:$N$100,8,False) | I12: =VLOOKUP(B12,Sheet1!$F$2:$N$100,9,False)
A13: TDK | B13: CGA3E2X7R2A103K080AA | C13: 4 | F13: =VLOOKUP(B13,Sheet1!$F$2:$N$100,6,False) -> Samsung | G13: =VLOOKUP(B13,Sheet1!$F$2:$N$100,7,False) -> CL10B103KC8WPNC | H13: =VLOOKUP(B13,Sheet1!$F$2:$N$100,8,False) | I13: =VLOOKUP(B13,Sheet1!$F$2:$N$100,9,False)
... A18: Taiyo Yuden | B18: HMK325B7225KMHP | C18: 4 | F18: =VLOOKUP(B18,Sheet1!$F$2:$N$100,6,False) -> Murata Electronics | G18: =VLOOKUP(B18,Sheet1!$F$2:$N$100,7,False) -> GCJ32DR72A225KA01L | H18: =VLOOKUP(B18,Sheet1!$F$2:$N$100,8,False) | I18: =VLOOKUP(B18,Sheet1!$F$2:$N$100,9,False)
A19: Molex | B19: 5051538000 | C19: 30
A20: Molex | B20: 5025790000 | C20: 22
A21: Nexperia | B21: BZT52H-B16-Q | C21: 1
A22: Vishay | B22: V35PWM15HM3/I | C22: 2
A23: Nexperia | B23: PMEG10010ELR-Q | C23: 3
A24: Nexperia | B24: BZX84-B5V6-Q | C24: 3
A25: Nexperia | B25: PTVS64VS1UR-Q | C25: 2
A26: Nexperia | B26: PTVS13VS1UR-Q | C26: 2
A27: Nexperia | B27: PESD5Z3.3,115 | C27: 2
A28: Nexperia | B28: PMEG10020ELR-Q | C28: 1
A29: Nexperia | B29: PMBD914-Q | C29: 6
A30: Nexperia | B30: BZX84-B4V3-Q | C30: 2
A31: LITTELFUSE | B31: ITV9550L5060MR | C31: 2 | D31: Dexerials | E31: SFK-5060
A32: Wurth Elektronik | B32: 7460408 | C32: 3
A33: Molex | B33: 5023521200 | C33: 1
A34: Molex | B34: 5031482270 | C34: 1
A35: Molex | B35: 502352-1000 | C35: 1 | F35: =VLOOKUP(B35,Sheet1!$F$2:$N$100,6,False) | G35: =VLOOKUP(B35,Sheet1!$F$2:$N$100,7,False) | H35: =VLOOKUP(B35,Sheet1!$F$2:$N$100,8,False) | I35: =VLOOKUP(B35,Sheet1!$F$2:$N$100,9,False)
A36: Bourns | B36: SRU1048A-560Y | C36: 1 | F36: =VLOOKUP(B36,Sheet1!$F$2:$N$100,6,False) | G36: =VLOOKUP(B36,Sheet1!$F$2:$N$100,7,False) | H36: =VLOOKUP(B36,Sheet1!$F$2:$N$100,8,False) | I36: =VLOOKUP(B36,Sheet1!$F$2:$N$100,9,False)
A37: TDK | B37: KLZ2012MHR4R7WTD25 | C37: 1 | F37: =VLOOKUP(B37,Sheet1!$F$2:$N$100,6,False) | G37: =VLOOKUP(B37,Sheet1!$F$2:$N$100,7,False) | H37: =VLOOKUP(B37,Sheet1!$F$2:$N$100,8,False) | I37: =VLOOKUP(B37,Sheet1!$F$2:$N$100,9,False)
A38: Bourns | B38: SRP2010DPA-4R7M | C38: 1 | F38: =VLOOKUP(B38,Sheet1!$F$2:$N$100,6,False) -> Murata Electronics | G38: =VLOOKUP(B38,Sheet1!$F$2:$N$100,7,False) -> DFE201610E-4R7M=P2 | H38: =VLOOKUP(B38,Sheet1!$F$2:$N$100,8,False) | I38: =VLOOKUP(B38,Sheet1!$F$2:$N$100,9,False)
A39: Inolux | B39: IN-S63AT5A | C39: 4 | F39: =VLOOKUP(B39,Sheet1!$F$2:$N$100,6,False) | G39: =VLOOKUP(B39,Sheet1!$F$2:$N$100,7,False) | H39: =VLOOKUP(B39,Sheet1!$F$2:$N$100,8,False) | I39: =VLOOKUP(B39,Sheet1!$F$2:$N$100,9,False)
A40: Murata Electronics | B40: PKLCS1212E40A1-R1 | C40: 1 | F40: =VLOOKUP(B40,Sheet1!$F$2:$N$100,6,False) | G40: =VLOOKUP(B40,Sheet1!$F$2:$N$100,7,False) | H40: =VLOOKUP(B40,Sheet1!$F$2:$N$100,8,False) | I40: =VLOOKUP(B40,Sheet1!$F$2:$N$100,9,False)
A41: Eaton | B41: NRSE104F3950B1F | C41: 5 | F41: =VLOOKUP(B41,Sheet1!$F$2:$N$100,6,False) | G41: =VLOOKUP(B41,Sheet1!$F$2:$N$100,7,False) | H41: =VLOOKUP(B41,Sheet1!$F$2:$N$100,8,False) | I41: =VLOOKUP(B41,Sheet1!$F$2:$N$100,9,False)
A42: Samtec | B42: 20021121-00010T1LF | C42: 1 | F42: =VLOOKUP(B42,Sheet1!$F$2:$N$100,6,False) -> Metz Connect USA | G42: =VLOOKUP(B42,Sheet1!$F$2:$N$100,7,False) -> PM20B05VBDN | H42: =VLOOKUP(B42,Sheet1!$F$2:$N$100,8,False) | I42: =VLOOKUP(B42,Sheet1!$F$2:$N$100,9,False)
A43: BX48-60 | B43: R7.12 | C43: 1
A44: Infineon Technologies | B44: BSS123NH6327XTSA1 | C44: 10
...

Sheet Sheet1
A1: Designator | B1: Comment | C1: Description | D1: Footprint | E1: Manufacturer | F1: Manufacturer Part Number | G1: Manufacturer (Alternate) | H1: Manufacturer Part Number (Alternate) | I1: Layer | J1: Quantity | K1: Alternate Manufacturer Part Number 2 | L1: Alternate Manufacturer 2 | M1: Alternate Manufacturer Part Number 3 | N1: Alternate Manufacturer 3
A2: C1, C2, C11, C12, C17, C18, C19, C21, C29, C30, C35, C36, C41, C42, C47, C48, C53, C54, C59, C60 | B2: AQ: 330nF 25V X7R 0603 10% | C2: Cap Ceramic 0.33uF 25V X7R 10% SMD 0603 125°C Punched Paper T/R | D2: CAPC1608X08N | E2: TDK | F2: CGA3E3X7R1E334K080AB | I2: Bottom, Top | J2: 20 | K2: Samsung | L2: CL10B334KA8VPNC
A3: C3, C4 | B3: AQ: 0.1UF 100V X7R 10% 0805 | C3: Cap Ceramic 0.1uF 100V X7R 10% Pad SMD 0805 125C Automotive T/R | D3: CAPC2012X10N | E3: KEMET | F3: C0805C104K1RACAUTO | I3: Top | J3: 2 | K3: Murata Electronics | L3: GCJ21BR72A104KA01L | M3: Samsung | N3: CL21B104KCFWPNE
A4: C5, C6, C23, C24, C115, C128, C132, C162, C173 | B4: AQ: 0.22uF 100V X7R 10% 0805 ESD | C4: CAP CER 0805 220NF 100V X7R ESD | D4: CAPC2012X10N | E4: KEMET | F4: C0805C224K1RECAUTO | I4: Bottom, Top, None | J4: 9
A5: C7, C8, C13, C14, C25, C26, C31, C32, C37, C38, C43, C44, C49, C50, C55, C56, C77, C78, C93, C101, C136, C139, C154, C155, C163, C164, C168 | B5: AQ: 1UF 25V X7R 0805 10% | C5: Multilayer Ceramic Capacitors MLCC - SMD/SMT CGA 0805 25V 1uF X7R 10% AEC-Q200 | D5: CAPC2012X10N | E5: TDK | F5: CGA4J3X7R1E105K125AB | I5: Top, Bottom | J5: 27 | K5: Samsung | L5: CL21B105KAFVPNE
A6: C9, C10, C15, C16, C27, C28, C33, C34, C39, C40, C45, C46, C51, C52, C57, C58, C138, C212 | B6: AQ: 0.22uF 16V X7R 10% 0603 ESD | C6: Cap Ceramic 0.22uF 16V X7R 10% Pad SMD 0603 125C Automotive T/R | D6: CAPC1608X08N | E6: KEMET | F6: C0603C224K4RECAUTO | I6: Bottom, Top | J6: 18 | K6: KEMET | L6: C0603C224K3RECAUTO | M6: KEMET | N6: C0603C224K3RECAUTO
A7: C20, C22, C63, C64, C65, C75, C76, C79, C86, C87, C91, C92, C94, C97, C98, C99, C104, C106, C107, C108, C111, C112, C113, C114, C117, C119, C120, C122, C125, C126, C127, C129, C130, C131, C133, C135, C140, C141, C143, C144, C145, C147, C148, C149, C150, C152, C156, C157, C158, C159, C161, C165, C166, C167, C169, C170, C174, C188, C191, C195, C202, C203, C204, C207, C209 | B7: AQ: 0.1UF 25V X7R 10% 0402 | C7: TDK - CGA2B3X7R1E104K050BB - KONDENSATOR, 0.1µF, 25V, 10%, X7R, 0402 | D7: CAPC1005X03N | E7: TDK | F7: CGA2B3X7R1E104K050BB | I7: Bottom, Top | J7: 65 | K7: Samsung | L7: CL05B104KA54PNC
A8: C61, C62, C73, C74, C105, C109, C137 | B8: AQ: 1nF 100V C0G 0805 5% | C8: Cap Ceramic Multilayer 0.001uF 250VDC 5% SMD Paper T/R | D8: CAPC2012X10N | E8: Murata | F8: GCM21A5C2E102JX01D | I8: Top, Bottom | J8: 7 | K8: TDK | L8: CGA4F3C0G2E102J085AA
A9: C66, C146, C151, C199 | B9: AQ: 1UF 25V X7R 0603 10% | C9: CAP CER 1UF 25V X7R 0603 | D9: CAPC1608X08N | E9: TDK | F9: CGA3E1X7R1E105K080AC | I9: Bottom | J9: 4 | K9: Samsung | L9: CL10B105KA8VPNC
A10: C67, C68, C80, C81 | B10: AQ: 220pF 50V C0G 0402 5% | C10: Cap Ceramic 220pF 50V C0G 5% SMD 0402 125C Automotive T/R | D10: CAPC1005X03N | E10: Murata | F10: GCM1555C1H221JA16D | I10: Top | J10: 4 | K10: Samsung | L10: CL05C221JB51PNC
A11: C69, C71, C82, C84, C88 | B11: AQ: 4.7NF 16V X7R 10% 0603 ESD | C11: Cap Ceramic 0.0047uF 16V X7R 10% SMD 0603 125°C Paper T/R | D11: CAPC1608X08N | E11: KEMET | F11: C0603C472K4RECAUTO | I11: Bottom | J11: 5
A12: C70, C72, C83, C85, C89, C190 | B12: AQ: 10NF 16V X7R 10% 0603 | C12: Cap Ceramic 0.01uF 16V X7R 10% Pad SMD 0603 125C Automotive T/R | D12: CAPC1608X08N | E12: KEMET | F12: C0603C103K4RECAUTO | I12: Bottom | J12: 6
A13: C100, C110, C116, C123 | B13: AQ: 0.01UF 100V X7R 0603 | C13: TDK - CGA3E2X7R2A103K080AA - SMD Multilayer Ceramic Capacitor, 10000 pF, 100 V, 0603 [1608 Metric], ± 10%, X7R, CGA Series | D13: CAPC1608X08N | E13: TDK | F13: CGA3E2X7R2A103K080AA | I13: Bottom, Top | J13: 4 | K13: Samsung | L13: CL10B103KC8WPNC
A14: C118, C180, C181, C189, C193, C194, C196, C197, C198, C200 | B14: AQ: 10UF 25V X7R 20% 1206 | C14: Multilayer Ceramic Capacitors MLCC -SMD/SMT 10uF 25V X7R +/-20% 1206 AEC-Q200 | D14: CAPC3216X18N | E14: Taiyo Yuden | F14: TMK316AB7106MLHT | I14: Top, Bottom | J14: 10 | K14: Samsung Electro-Mech | L14: CL31B106KAHVPNE
A15: C153, C184 | B15: AQ: 47pF 50V C0G 5% 0402 | C15: AC Series 0402 47 pF 50 V ±5% NP0/C0G Multilayer Ceramic Capacitor | D15: CAPC1005X03N | E15: Yageo | F15: AC0402JRNPO9BN470 | I15: None, Top | J15: 2 | K15: Murata Electronics | L15: GCM1555C1H470JA16D | M15: Samsung | N15: CL05C470JB51PNC
A16: C171, C172 | B16: AQ: 12PF 50V C0G ±0.5PF 0402 | C16: 0402 12pF 50V ±0.5 pF Tolerance C0G SMT Multilayer Ceramic Capacitor | D16: CAPC1005X03N | E16: Murata | F16: GCM1555C1H120JA16J | I16: Top | J16: 2 | K16: Samsung | L16: CL05C120JB51PNC
A17: C176, C177 | B17: AQ: 2.2nF 50V X7R 10% 0402 | C17: MLCC 0.0022uF 50V X7R 10% Pad SMD 0402 125C Automotive T/R | D17: CAPC1005X03N | E17: Taiyo Yuden | F17: UMK105B7222KVHF | I17: Top, Bottom | J17: 2 | K17: Murata Electronics | L17: GCM155R71H222KA37D
A18: C183, C185, C187, C210 | B18: AQ: 2.2UF 100V X7R 10% 1210 | C18: Multilayer Ceramic Capacitors MLCC -SMD/SMT 2.2uF 100V X7R +/-10% 1210 AEC-Q200 | D18: CAPC3325X06N | E18: Taiyo Yuden | F18: HMK325B7225KMHP | I18: Bottom, Top | J18: 4 | K18: Murata Electronics | L18: GCJ32DR72A225KA01L
A19: COATING1 | B19: Conformal Coating | C19: HumiSeal® 1A33 Urethane Conformal Coating | E19: Chase Corp | F19: HumiSeal® 1A33 | I19: None | J19: 1
A20: CRMP1, CRMP4, CRMP5, CRMP8, CRMP9, CRMP12, CRMP13, CRMP16, CRMP17, CRMP20, CRMP21, CRMP24, CRMP25, CRMP28, CRMP29, CRMP32, CRMP33, CRMP36, CRMP37, CRMP40, CRMP43, CRMP44 | B20: CRIMP: 5051538000 MLX-DURA | C20: DuraClik TPA Wire-to-Board Crimp Receptacle Terminal, Female, Tin Plating | E20: Molex | F20: 5051538000 | I20: None | J20: 22
A21: CRMP2, CRMP3, CRMP6, CRMP7, CRMP10, CRMP11, CRMP14, CRMP15, CRMP18, CRMP19, CRMP22, CRMP23, CRMP26, CRMP27, CRMP30, CRMP31, CRMP34, CRMP35, CRMP38, CRMP39, CRMP41, CRMP42 | B21: CRIMP: 5025790000 MLX-CLK | C21: CONN 24-28AWG CRIMP TIN | E21: Molex | F21: 5025790000 | I21: None | J21: 22
A22: D1, D13 | B22: AQ: ZD_16V 0.5W SOD123 | C22: DIODE ZENER 16V 500MW SOD123 | D22: SODFL350X110-2N | E22: Nexperia | F22: BZT52H-B16-Q | I22: Bottom | J22: 2
A23: D2_1, D3_1 | B23: AQ: SD_150V 35A TO-252AE | C23: Diode Schottky 150V 35A Slimdpak | D23: DPAK229P900X140-3M | E23: Vishay | F23: V35PWM15HM3/I | I23: Bottom, Top | J23: 2
A24: D6, D12, D18 | B24: AQ: SD_100V 1A SOD-123W | C24: DIODE SCHOTTKY 100V 1A SOD123 | D24: SODFL350X110-2N | E24: Nexperia | F24: PMEG10010ELR-Q | I24: Top, Bottom | J24: 3
A25: D7, D14, D15 | B25: AQ: ZD_5V6 0.25W SOT23 | C25: DIODE ZENER 5.6V 250MW SOT23 | D25: SOT95P250X112-3N | E25: Nexperia | F25: BZX84-B5V6-Q | I25: Bottom | J25: 3
A26: D8, D17 | B26: AQ: TVS_64V 400W SOD-123W | C26: TVS DIODE 64VWM 103VC SOD123W | D26: SODFL350X110-2N | E26: Nexperia | F26: PTVS64VS1UR-Q | I26: Bottom | J26: 2
A27: D9, D11 | B27: AQ: TVS_13V 400W SOD-123W | C27: TVS DIODE 13VWM 21.5VC SOD123W | D27: SODFL350X110-2N | E27: Nexperia | F27: PTVS13VS1UR-Q | I27: Bottom | J27: 2
A28: D16 | B28: AQ: SD_100V 2A SOD-123W | C28: DIODE SCHOTTKY 100V 2A SOD123W | D28: SODFL350X110-2N | E28: Nexperia | F28: PMEG10020ELR-Q | I28: Top | J28: 1
A29: D19, D22, D23, D24, D25, D26 | B29: AQ: D_100V 0.215A SOT-23 | C29: PMBD914-Q - High-speed switching diode | D29: SOT95P250X112-3N | E29: Nexperia | F29: PMBD914-Q | I29: Bottom, Top | J29: 6
A30: D20, D21 | B30: AQ: ZD_4V3 0.25W SOD123 | C30: DIODE ZENER 4.3V 250MW SOT23 | D30: SOT95P250X112-3N | E30: Nexperia | F30: BZX84-B4V3-Q | I30: Top | J30: 2
A31: F1, F2 | B31: F: 80V 60A LittleFuse | C31: Chip type surface mountable device that can protect against both overcurrent and overcharging,60A AC 80 V DC Fuse Board Mount Surface Mount. | D31: ITV9550L5060MR | E31: LITTELFUSE | F31: ITV9550L5060MR | I31: Bottom, Top | J31: 2
A32: J1, J2, J8 | B32: CON PWR: 7460408 | C32: WP-BUCF REDCUBE PRESS-FIT with internal thread, circumference, L9W9H6mm, M5 x 6mm, 175A | D32: 7460408_chemical surface | E32: Wurth Elektronik | F32: 7460408 | I32: Top | J32: 3
A33: J3 | B33: CONN12: 5023521200 | C33: DuraClik Wire-to-Board Header, Single Row, Right-Angle, 12 Circuits, Tin (Sn) Plating, Natural | D33: CONN12: 5023521200 | E33: Molex | F33: 5023521200 | I33: Top | J33: 1
A34: J4 | B34: CONN 22: 5031482270 | C34: Clik-Mate1.5 Drra Smt Sn Hbp Etp 22P Nat |Molex 503148-2270 | D34: CONN 22: 2132282210 | E34: Molex | F34: 5031482270 | I34: Top | J34: 1
A35: J5 | B35: CONN 10: 5023521000 | C35: DuraClik Wire-to-Board Header, Single Row, Right-Angle, 10 Circuits, Tin (Sn) Plating, Natural | D35: FP-5023521010-MFG | E35: Molex | F35: 502352-1000 | I35: Top | J35: 1
A36: L1 | B36: AQ: 56UH 1.4A 0.11R | C36: Ind Power Shielded Wirewound 56uH 30% 100KHz 26Q-Factor Ferrite 1.6A T/R | D36: SRU_IND_BOURNS | E36: Bourns | F36: SRU1048A-560Y | I36: Top | J36: 1
A37: L2 | B37: AQ: 4.7UH 0.5A 0.39R | C37: FIXED IND 4.7UH 500MA 390MOHM SM | D37: INDC2012X08M | E37: TDK | F37: KLZ2012MHR4R7WTD25 | I37: Bottom | J37: 1
A38: L3 | B38: AQ: 4.7UH 1.1A 0.36R | C38: Ind, 2x1.6x1mm, 4.7uH 20%, 1.1A, shd | D38: INDC2116X10N | E38: Bourns | F38: SRP2010DPA-4R7M | I38: Top | J38: 1 | K38: Murata Electronics | L38: DFE201610E-4R7M=P2
A39: LD1, LD2, LD3, LD5 | B39: AQ: LD_RED 2mA 0603 | C39: LED Uni-Color Amber 609nm Automotive 2-Pin Chip 0603(1608Metric) T/R | D39: 0603 LED | E39: Inolux | F39: IN-S63AT5A | I39: Top | J39: 4
A40: LS1 | B40: BUZ: PKLCS1212E40A1-R1 | C40: Audio Sounder Piezo 25Vp-p 3Vp-p 75dBA Solder Pad Surface Mount T/R Automotive | D40: BUZ: PKLCS1212E40A1-R1 | E40: Murata Electronics | F40: PKLCS1212E40A1-R1 | I40: Top | J40: 1
...
